Workbook

Sheet Summary
A1: Data Centre Electrical Design: 2N architecture (summary)
A2: 1 MW IT scenario. All values link to the calculation sheets. Change Inputs to re-size the design.
A4: Item | B4: Result | C4: Unit | D4: Where calculated
A5: IT load | B5: =Inputs!$B$8 -> 1000 | C5: kW | D5: Inputs
A6: Total facility load | B6: =Inputs!$B$12 -> 1500 | C6: kW | D6: Inputs
A7: PUE | B7: =Inputs!$B$13 -> 1.5 | C7: - | D7: Inputs
A8: Design load per path (failover + growth) | B8: =Load_Calc!$B$19 -> 2000 | C8: kVA | D8: Load_Calc
A9: Transformer per path | B9: =Sizing!$B$7 -> 2500 | C9: kVA | D9: Sizing
A10: Transformer loading, normal / failover | B10: =TEXT(Sizing!$B$10,"0%")&" / "&TEXT(Sizing!$B$11,"0%") -> 33% / 67% | D10: Sizing
A11: UPS per path | B11: =Sizing!$B$16 -> 1200 | C11: kVA | D11: Sizing
A12: UPS loading, normal / failover | B12: =TEXT(Sizing!$B$17,"0%")&" / "&TEXT(Sizing!$B$18,"0%") -> 42% / 83% | D12: Sizing
A13: Battery per UPS (installed) | B13: =Sizing!$B$28&" strings x "&Inputs!$B$36&" Ah, "&Sizing!$B$26&" V, "&Inputs!$B$30&" min" -> 4 strings x 300 Ah, 480 V, 10 min | D13: Sizing
A14: Generator per path | B14: =Sizing!$B$36 -> 2500 | C14: kVA | D14: Sizing
A15: Fuel tank per generator | B15: =Sizing!$B$43 -> 9720 | C15: L | D15: Sizing
A16: PDUs per path | B16: =Inputs!$B$45&" x "&Sizing!$B$46&" kVA" -> 4 x 400 kVA | D16: Sizing
A17: Fault level at LV bus (incl. motors) | B17: =ShortCircuit!$C$17 -> 51.246027 | C17: kA | D17: ShortCircuit
A18: LV equipment breaking rating | B18: =ShortCircuit!$E$17 -> 65 | C18: kA | D18: ShortCircuit
A19: Voltage drop, UPS output to rack | B19: =Cables!$P$10 -> 0.023692347 | D19: Cables
A20: Availability, single path | B20: =Reliability!$B$23 -> 0.9992304 | D20: Reliability
A21: Availability, 2N | B21: =Reliability!$B$25 -> 0.99999171 | D21: Reliability
A22: Expected downtime, 2N | B22: =Reliability!$E$25 -> 4.3563427 | C22: min/year | D22: Reliability
A23: Expected downtime, single path | B23: =Reliability!$D$23 -> 6.7417257 | C23: h/year | D23: Reliability
A25: Design checks
A26: Check | B26: Status
A27: Transformer loading (failover + growth) within limit | B27: =IF(Sizing!$B$12<=Inputs!$B$17,"OK","FAIL") -> OK
A28: UPS can carry 100% IT load after other path fails | B28: =IF(Sizing!$B$18<=1,"OK","FAIL") -> OK
A29: PDU can carry 100% IT load after other path fails | B29: =IF(Sizing!$B$47<=1,"OK","FAIL") -> OK
A30: Generator covers failover facility load | B30: =IF(Sizing!$B$38<=1,"OK","FAIL") -> OK
A31: Cable ampacity (all feeders) | B31: =IF(COUNTIF(Cables!$L$5:$L$8,"FAIL")=0,"OK","FAIL") -> OK
A32: Cable voltage drop (all feeders and total) | B32: =IF(COUNTIF(Cables!$R$5:$R$8,"FAIL")+COUNTIF(Cables!$R$10,"FAIL")=0,"OK","FAIL") -> OK
A33: Cable short-circuit withstand | B33: =IF(COUNTIF(Cables!$V$5:$V$8,"FAIL")=0,"OK","FAIL") -> OK
A34: Breaking capacity >= fault level (all points) | B34: =IF(COUNTIF(ShortCircuit!$F$16:$F$21,"FAIL")+COUNTIF(Protection!$L$5:$L$10,"FAIL")=0,"OK","FAIL") -> OK
A35: Breaker frame and Ir coordination with load | B35: =IF(COUNTIF(Protection!$J$5:$J$10,"FAIL")=0,"OK","FAIL") -> OK
A36: MV relay graded above LV main ACB | B36: =IF(Protection!$B$21="OK","OK","FAIL") -> OK
A37: Rack branch current within 80% of breaker | B37: =IF(Sizing!$B$52="OK","OK","FAIL") -> OK
A38: Overall | B38: =IF(COUNTIF(B27:B37,"FAIL")=0,"ALL CHECKS PASS","REVIEW FAILED CHECKS") -> ALL CHECKS PASS
A40: Sheets: Inputs > Load_Calc > Sizing > Cables > ShortCircuit > Protection > Reliability > Failure_Scenarios > BOM > Std_Sizes
A41: Colour legend: blue on yellow = input; black = formula; green = link from another sheet. Hardcoded assumptions are documented next to the cell.

Sheet Inputs
A1: Inputs and design basis
A2: Blue text on yellow = editable input. Black = formula. All other sheets recalculate from here.
A4: Parameter | B4: Value | C4: Unit | D4: Source / remark
A5: 1. Facility load definition
A6: Number of racks | B6: 200 | C6: nos | D6: Project scenario (assumption)
A7: Average IT load per rack | B7: 5 | C7: kW | D7: Typical enterprise / colocation density
A8: Total IT load | B8: =Inputs!$B$6*Inputs!$B$7 -> 1000 | C8: kW | D8: Calculated
A9: Cooling load (chillers, CRAH, pumps) | B9: 400 | C9: kW | D9: Assumption: ~80% of overhead so that PUE ≈ 1.5
A10: Lighting, security, BMS, fire and other auxiliaries | B10: 60 | C10: kW | D10: Assumption
A11: UPS and distribution losses | B11: 40 | C11: kW | D11: Assumption: ~4% of IT load
A12: Total facility load | B12: =Inputs!$B$8+Inputs!$B$9+Inputs!$B$10+Inputs!$B$11 -> 1500 | C12: kW | D12: Calculated
A13: PUE (derived) | B13: =Inputs!$B$12/Inputs!$B$8 -> 1.5 | C13: - | D13: Target about 1.5
A14: 2. Electrical design basis
A15: Facility power factor at LV (before correction) | B15: 0.9 | C15: - | D15: Assumption (mixed IT + mechanical load)
A16: Future growth margin | B16: 0.2 | C16: - | D16: Design margin on load (20-30% typical)
A17: Maximum transformer loading at design (failover + growth) | B17: 0.85 | C17: - | D17: Design rule: keep thermal margin
A18: Utility MV supply voltage | B18: 11 | C18: kV | D18: Typical DISCOM supply; confirm with PSPCL
A19: LV system voltage | B19: 415 | C19: V | D19: 3-phase 4-wire, 50 Hz, TN-S
A20: Utility fault level at 11 kV | B20: 250 | C20: MVA | D20: ASSUMPTION (about 13 kA). Obtain the real value from the DISCOM
A21: Transformer impedance | B21: 0.0625 | C21: pu | D21: 6.25% typical for 2500 kVA (IS 2026)
A22: Design ambient temperature | B22: 45 | C22: °C | D22: Punjab summer design condition
A23: Temperature derating factor, XLPE at 45°C | B23: 0.87 | C23: - | D23: IEC 60364-5-52 (reference 30°C)
A24: Grouping derating factor | B24: 0.8 | C24: - | D24: Multiple circuits on a tray (assumption)
A25: 3. UPS and battery
A26: UPS output power factor (kW/kVA) | B26: 1 | C26: - | D26: Modern double-conversion UPS (IEC 62040-3)
A27: UPS efficiency (double conversion) | B27: 0.96 | C27: - | D27: Typical 95-97%
A28: Battery recharge allowance on UPS input | B28: 1.1 | C28: - | D28: 10% extra input while recharging
A29: UPS input power factor | B29: 0.99 | C29: - | D29: Active / IGBT front end
A30: Battery autonomy | B30: 10 | C30: min | D30: Typical 5-15 min until generator is stable
A31: Number of VRLA cells per string | B31: 240 | C31: nos | D31: 240 cells x 2 V = 480 V nominal DC bus
A32: End-of-discharge voltage per cell | B32: 1.67 | C32: V | D32: Typical for high-rate discharge
A33: Battery ageing factor | B33: 1.25 | C33: - | D33: End of life at 80% capacity
A34: Battery design margin | B34: 1.1 | C34: -
A35: Usable fraction of nominal energy at 10 min rate | B35: 0.55 | C35: - | D35: PRELIMINARY. Validate with manufacturer constant-power tables
A36: Battery string capacity (nominal) | B36: 300 | C36: Ah | D36: Selected block size (assumption)
A37: 4. Generator
A38: Generator power factor | B38: 0.8 | C38: - | D38: Standard genset rating
A39: Derating for UPS rectifier harmonics and step load | B39: 1.1 | C39: - | D39: 1.10 for active front end; 1.25-1.4 for 6-pulse rectifier
A40: Generator sub-transient reactance X''d | B40: 0.12 | C40: pu | D40: Typical 10-15%
A41: Extra standby gensets per path (N+1) | B41: 0 | C41: nos | D41: 0 = one genset per path. Set 1 for N+1 per path
...

Sheet Load_Calc
A1: Step 1: Load calculation
A2: Each path (A or B) must carry the complete facility load when the other path is lost (2N).
A4: Parameter | B4: Value | C4: Unit | D4: Source / remark
A5: Facility load
A6: IT load | B6: =Inputs!$B$8 -> 1000 | C6: kW
A7: Cooling | B7: =Inputs!$B$9 -> 400 | C7: kW
A8: Auxiliaries | B8: =Inputs!$B$10 -> 60 | C8: kW
A9: UPS and distribution losses | B9: =Inputs!$B$11 -> 40 | C9: kW
A10: Total facility load | B10: =Inputs!$B$12 -> 1500 | C10: kW
A11: Total facility apparent power | B11: =Inputs!$B$12/Inputs!$B$15 -> 1666.6667 | C11: kVA | D11: kW / power factor
A12: Per-path loading
A13: Each path, normal operation (50% share) | B13: =Inputs!$B$12/2 -> 750 | C13: kW | D13: A and B share load equally
A14: Each path, normal operation | B14: =Load_Calc!$B$11/2 -> 833.33333 | C14: kVA
A15: Each path, failover (100% of load) | B15: =Inputs!$B$12 -> 1500 | C15: kW | D15: One path carries everything after the other fails
A16: Each path, failover | B16: =Load_Calc!$B$11 -> 1666.6667 | C16: kVA
A17: Design values with growth margin
A18: Design load per path (failover + growth) | B18: =Inputs!$B$12*(1+Inputs!$B$16) -> 1800 | C18: kW
A19: Design apparent power per path | B19: =Load_Calc!$B$11*(1+Inputs!$B$16) -> 2000 | C19: kVA | D19: Used for transformer sizing
A20: Design IT load per path (failover + growth) | B20: =Inputs!$B$8*(1+Inputs!$B$16) -> 1200 | C20: kW | D20: Used for UPS and PDU sizing
A25: Load breakdown | B25: kW | C25: % of total
A26: IT load | B26: =Inputs!$B$8 -> 1000 | C26: =B26/Inputs!$B$12 -> 0.66666667
A27: Cooling | B27: =Inputs!$B$9 -> 400 | C27: =B27/Inputs!$B$12 -> 0.26666667
A28: Auxiliaries | B28: =Inputs!$B$10 -> 60 | C28: =B28/Inputs!$B$12 -> 0.04
A29: Losses | B29: =Inputs!$B$11 -> 40 | C29: =B29/Inputs!$B$12 -> 0.026666667

Sheet Sizing
A1: Step 3: Equipment sizing (per path)
A2: Quantities in the BOM are per path x 2. Results update from Inputs.
A4: Parameter | B4: Value | C4: Unit | D4: Source / remark
A5: Transformer
A6: Required kVA = design kVA / max loading | B6: =Load_Calc!$B$19/Inputs!$B$17 -> 2352.9412 | C6: kVA
A7: Selected transformer | B7: =IFERROR(INDEX(Std_Sizes!$A$3:$A$9,COUNTIF(Std_Sizes!$A$3:$A$9,"<"&(Sizing!$B$6))+1),"EXCEEDS LIST") -> 2500 | C7: kVA | D7: Next standard size. 11/0.415 kV, Dyn11, ONAN, Z = 6.25%
A8: LV full-load current | B8: =Sizing!$B$7*1000/(SQRT(3)*Inputs!$B$19) -> 3478.0137 | C8: A
A9: MV full-load current | B9: =Sizing!$B$7*1000/(SQRT(3)*Inputs!$B$18*1000) -> 131.21597 | C9: A
A10: Loading, normal (50% share) | B10: =Load_Calc!$B$14/Sizing!$B$7 -> 0.33333333
A11: Loading, failover (100%) | B11: =Load_Calc!$B$16/Sizing!$B$7 -> 0.66666667 | D11: Without growth margin
A12: Loading, failover + growth | B12: =Load_Calc!$B$19/Sizing!$B$7 -> 0.8 | D12: Must be <= max loading
A13: TR secondary busduct / ACB frame | B13: =IFERROR(INDEX(Std_Sizes!$G$3:$G$13,COUNTIF(Std_Sizes!$G$3:$G$13,"<"&(Sizing!$B$8))+1),"EXCEEDS LIST") -> 4000 | C13: A | D13: Smallest standard frame >= full-load current
A14: UPS
A15: Required UPS = design IT load / UPS PF | B15: =Load_Calc!$B$20/Inputs!$B$26 -> 1200 | C15: kVA
A16: Selected UPS (per path) | B16: =IFERROR(INDEX(Std_Sizes!$B$3:$B$11,COUNTIF(Std_Sizes!$B$3:$B$11,"<"&(Sizing!$B$15))+1),"EXCEEDS LIST") -> 1200 | C16: kVA | D16: Next standard size
A17: UPS loading, normal (50% IT) | B17: =(Inputs!$B$8/2/Inputs!$B$26)/Sizing!$B$16 -> 0.41666667 | D17: Note: UPS efficiency falls at low load
A18: UPS loading, failover (100% IT) | B18: =(Inputs!$B$8/Inputs!$B$26)/Sizing!$B$16 -> 0.83333333 | D18: Must be <= 100%
A19: UPS output current at rated load | B19: =Sizing!$B$16*1000/(SQRT(3)*Inputs!$B$19) -> 1669.4466 | C19: A
A20: UPS input apparent power (incl. battery recharge) | B20: =Sizing!$B$16*Inputs!$B$26/Inputs!$B$27*Inputs!$B$28/Inputs!$B$29 -> 1388.8889 | C20: kVA
A21: UPS input current | B21: =Sizing!$B$20*1000/(SQRT(3)*Inputs!$B$19) -> 1932.2298 | C21: A
A22: Battery (preliminary, validate against manufacturer discharge tables)
A23: DC power at rated UPS load | B23: =Sizing!$B$16*Inputs!$B$26/Inputs!$B$27 -> 1250 | C23: kW
A24: Energy for autonomy | B24: =Sizing!$B$23*Inputs!$B$30/60 -> 208.33333 | C24: kWh
A25: Nominal energy needed (ageing, margin, usable fraction) | B25: =Sizing!$B$24*Inputs!$B$33*Inputs!$B$34/Inputs!$B$35 -> 520.83333 | C25: kWh
A26: Nominal DC bus voltage | B26: =Inputs!$B$31*2 -> 480 | C26: V
A27: Required capacity at nominal voltage | B27: =Sizing!$B$25*1000/Sizing!$B$26 -> 1085.0694 | C27: Ah
A28: Number of strings | B28: =ROUNDUP(Sizing!$B$27/Inputs!$B$36,0) -> 4 | C28: nos
A29: Installed capacity | B29: =Sizing!$B$28*Inputs!$B$36 -> 1200 | C29: Ah
A30: Installed nominal energy | B30: =Sizing!$B$29*Sizing!$B$26/1000 -> 576 | C30: kWh
A31: Discharge current at end-of-discharge voltage | B31: =Sizing!$B$23*1000/(Inputs!$B$31*Inputs!$B$32) -> 3118.7625 | C31: A
A32: Discharge current per string | B32: =Sizing!$B$31/Sizing!$B$28 -> 779.69062 | C32: A
A33: Generator
A34: Required kW = design load x harmonic/step derating | B34: =Load_Calc!$B$18*Inputs!$B$39 -> 1980 | C34: kW
A35: Required kVA | B35: =Sizing!$B$34/Inputs!$B$38 -> 2475 | C35: kVA
A36: Selected genset | B36: =IFERROR(INDEX(Std_Sizes!$C$3:$C$10,COUNTIF(Std_Sizes!$C$3:$C$10,"<"&(Sizing!$B$35))+1),"EXCEEDS LIST") -> 2500 | C36: kVA | D36: Next standard size
A37: Genset kW rating | B37: =Sizing!$B$36*Inputs!$B$38 -> 2000 | C37: kW
A38: Genset loading at present failover load | B38: =Inputs!$B$12/Sizing!$B$37 -> 0.75
A39: Genset loading when both gensets share load | B39: =Inputs!$B$12/2/Sizing!$B$37 -> 0.375 | D39: Below ~30% risks wet stacking. Plan load-bank tests
A40: Gensets per path (N + extra) | B40: =1+Inputs!$B$41 -> 1 | C40: nos
A41: Genset full-load current | B41: =Sizing!$B$36*1000/(SQRT(3)*Inputs!$B$19) -> 3478.0137 | C41: A
...

Sheet Cables
A1: Step 3b: Cable sizing and voltage drop
A2: Cu XLPE cable. Number of parallel runs is calculated so that derated ampacity >= load current. Voltage-drop limit 3% per feeder.
A4: Feeder | B4: Load current Ib (A) | C4: Voltage (V) | D4: Phases | E4: Length (m) | F4: cos φ | G4: Cable size (mm²) | H4: Ampacity per run (A) | I4: Derating | J4: Parallel runs | K4: Installed capacity (A) | L4: Ampacity check | M4: R (Ω/km) | N4: X (Ω/km) | O4: Voltage drop (V) | P4: Voltage drop (%) | Q4: Limit (%) | R4: VD check | S4: Fault at source (kA) | T4: Clearing time (s) | U4: Min size per run, adiabatic (mm²) | V4: Withstand check
A5: LV essential board to UPS input | B5: =Sizing!$B$21 -> 1932.2298 | C5: =Inputs!$B$19 -> 415 | D5: 3 | E5: =Inputs!$B$56 -> 40 | F5: 0.99 | G5: 300 | H5: =INDEX(Std_Sizes!$L$3:$L$15,MATCH(G5,Std_Sizes!$K$3:$K$15,0)) -> 631 | I5: =Inputs!$B$23*Inputs!$B$24 -> 0.696 | J5: =ROUNDUP(B5/(H5*I5),0) -> 5 | K5: =H5*I5*J5 -> 2195.88 | L5: =IF(K5>=B5,"OK","FAIL") -> OK | M5: =INDEX(Std_Sizes!$M$3:$M$15,MATCH(G5,Std_Sizes!$K$3:$K$15,0)) -> 0.077 | N5: =INDEX(Std_Sizes!$N$3:$N$15,MATCH(G5,Std_Sizes!$K$3:$K$15,0)) -> 0.071 | O5: =IF(D5=3,SQRT(3),2)*(B5/J5)*E5/1000*(M5*F5+N5*SQRT(1-F5^2)) -> 2.309124 | P5: =O5/C5 -> 0.0055641543 | Q5: 0.03 | R5: =IF(P5<=Q5,"OK","FAIL") -> OK | S5: =ShortCircuit!$C$17 -> 51.246027 | T5: 0.3 | U5: =S5*1000/J5*SQRT(T5)/143 -> 39.25679 | V5: =IF(G5>=U5,"OK","FAIL") -> OK
A6: UPS output board to PDU | B6: =Sizing!$B$48 -> 556.48219 | C6: =Inputs!$B$19 -> 415 | D6: 3 | E6: =Inputs!$B$57 -> 30 | F6: 0.95 | G6: 185 | H6: =INDEX(Std_Sizes!$L$3:$L$15,MATCH(G6,Std_Sizes!$K$3:$K$15,0)) -> 460 | I6: =Inputs!$B$23*Inputs!$B$24 -> 0.696 | J6: =ROUNDUP(B6/(H6*I6),0) -> 2 | K6: =H6*I6*J6 -> 640.32 | L6: =IF(K6>=B6,"OK","FAIL") -> OK | M6: =INDEX(Std_Sizes!$M$3:$M$15,MATCH(G6,Std_Sizes!$K$3:$K$15,0)) -> 0.126 | N6: =INDEX(Std_Sizes!$N$3:$N$15,MATCH(G6,Std_Sizes!$K$3:$K$15,0)) -> 0.073 | O6: =IF(D6=3,SQRT(3),2)*(B6/J6)*E6/1000*(M6*F6+N6*SQRT(1-F6^2)) -> 2.0601577 | P6: =O6/C6 -> 0.0049642355 | Q6: 0.03 | R6: =IF(P6<=Q6,"OK","FAIL") -> OK | S6: =ShortCircuit!$C$18 -> 41.080729 | T6: 0.2 | U6: =S6*1000/J6*SQRT(T6)/143 -> 64.237275 | V6: =IF(G6>=U6,"OK","FAIL") -> OK
A7: LV essential board to mechanical MCC | B7: =(Inputs!$B$9+Inputs!$B$10)*1000/(SQRT(3)*Inputs!$B$19*0.85) -> 752.88766 | C7: =Inputs!$B$19 -> 415 | D7: 3 | E7: =Inputs!$B$58 -> 60 | F7: 0.85 | G7: 240 | H7: =INDEX(Std_Sizes!$L$3:$L$15,MATCH(G7,Std_Sizes!$K$3:$K$15,0)) -> 546 | I7: =Inputs!$B$23*Inputs!$B$24 -> 0.696 | J7: =ROUNDUP(B7/(H7*I7),0) -> 2 | K7: =H7*I7*J7 -> 760.032 | L7: =IF(K7>=B7,"OK","FAIL") -> OK | M7: =INDEX(Std_Sizes!$M$3:$M$15,MATCH(G7,Std_Sizes!$K$3:$K$15,0)) -> 0.096 | N7: =INDEX(Std_Sizes!$N$3:$N$15,MATCH(G7,Std_Sizes!$K$3:$K$15,0)) -> 0.072 | O7: =IF(D7=3,SQRT(3),2)*(B7/J7)*E7/1000*(M7*F7+N7*SQRT(1-F7^2)) -> 4.6760915 | P7: =O7/C7 -> 0.01126769 | Q7: 0.03 | R7: =IF(P7<=Q7,"OK","FAIL") -> OK | S7: =ShortCircuit!$C$17 -> 51.246027 | T7: 0.3 | U7: =S7*1000/J7*SQRT(T7)/143 -> 98.141975 | V7: =IF(G7>=U7,"OK","FAIL") -> OK
A8: RPP to rack branch (1-phase) | B8: =Sizing!$B$51 -> 22.883295 | C8: =Inputs!$B$49 -> 230 | D8: 1 | E8: =Inputs!$B$59 -> 25 | F8: 0.95 | G8: 6 | H8: =INDEX(Std_Sizes!$L$3:$L$15,MATCH(G8,Std_Sizes!$K$3:$K$15,0)) -> 54 | I8: =Inputs!$B$23*Inputs!$B$24 -> 0.696 | J8: =ROUNDUP(B8/(H8*I8),0) -> 1 | K8: =H8*I8*J8 -> 37.584 | L8: =IF(K8>=B8,"OK","FAIL") -> OK | M8: =INDEX(Std_Sizes!$M$3:$M$15,MATCH(G8,Std_Sizes!$K$3:$K$15,0)) -> 3.93 | N8: =INDEX(Std_Sizes!$N$3:$N$15,MATCH(G8,Std_Sizes!$K$3:$K$15,0)) -> 0.1 | O8: =IF(D8=3,SQRT(3),2)*(B8/J8)*E8/1000*(M8*F8+N8*SQRT(1-F8^2)) -> 4.3074657 | P8: =O8/C8 -> 0.018728112 | Q8: 0.03 | R8: =IF(P8<=Q8,"OK","FAIL") -> OK | S8: =ShortCircuit!$C$19 -> 29.887589 | T8: MCB let-through | U8: =SQRT($B$17)/143 -> 1.6400055 | V8: =IF(G8>=U8,"OK","FAIL") -> OK
A10: Total voltage drop, UPS output to rack (feeder 2 + feeder 4) | P10: =P6+P8 -> 0.023692347 | Q10: 0.05 | R10: =IF(P10<=Q10,"OK","FAIL") -> OK
A12: Notes:
A13: 1. Derating = temperature factor x grouping factor (Inputs). Ampacity table is indicative; verify with vendor data.
A14: 2. Voltage drop: 3-phase = √3·I·L·(R·cosφ + X·sinφ); 1-phase = 2·I·L·(R·cosφ + X·sinφ). Per-run current used.
A15: 3. Adiabatic check: S >= I·√t / k with k = 143 (Cu, XLPE 90°C to 250°C, IEC 60364-4-43), assuming equal current sharing between parallel runs.
A16: 4. Busduct (not cable) is proposed for transformer-to-LV board and generator-to-ATS links, rated per Sizing sheet.
A17: Rack MCB let-through energy I²t (A²s) | B17: 55000 | C17: ASSUMPTION: typical class-3 32 A MCB (EN 60898). Verify with the breaker datasheet.

Sheet ShortCircuit
A1: Step 4a: Short-circuit calculation
A2: Balanced 3-phase fault, impedance method. Impedances summed arithmetically (conservative). Verify with ETAP/pandapower for final design.
A4: Parameter | B4: Value | C4: Unit | D4: Source / remark
A5: Source and transformer
A6: Base impedance at LV (V² / S) | B6: =(Inputs!$B$19/1000)^2/(Sizing!$B$7/1000)*1000 -> 68.89 | C6: mΩ
A7: Utility source impedance on transformer base | B7: =(Sizing!$B$7/1000)/Inputs!$B$20 -> 0.01 | C7: pu
A8: Total source + transformer impedance | B8: =ShortCircuit!$B$7+Inputs!$B$21 -> 0.0725 | C8: pu
A9: Total impedance at LV bus | B9: =ShortCircuit!$B$8*ShortCircuit!$B$6 -> 4.994525 | C9: mΩ
A10: Fault current from utility at LV bus | B10: =Inputs!$B$19/(SQRT(3)*ShortCircuit!$B$9/1000)/1000 -> 47.972602 | C10: kA
A11: Motor full-load current | B11: =Inputs!$B$52*1000/(SQRT(3)*Inputs!$B$19*Inputs!$B$53) -> 654.68493 | C11: A
A12: Motor contribution | B12: =Inputs!$B$54*ShortCircuit!$B$11/1000 -> 3.2734246 | C12: kA
A14: Fault levels and equipment rating
A15: Fault point | B15: Impedance to point (mΩ) | C15: Fault current (kA) | D15: Note | E15: Selected breaking rating (kA) | F15: Check
A16: F1 MV bus (11 kV) | C16: =Inputs!$B$20/(SQRT(3)*Inputs!$B$18) -> 13.121597 | D16: MV switchgear rating | E16: =IFERROR(INDEX(Std_Sizes!$F$3:$F$8,COUNTIF(Std_Sizes!$F$3:$F$8,"<"&(C16))+1),"EXCEEDS LIST") -> 16 | F16: =IF(E16>=C16,"OK","FAIL") -> OK
A17: F2 LV essential bus (incl. motors) | B17: =ShortCircuit!$B$9 -> 4.994525 | C17: =ShortCircuit!$B$10+ShortCircuit!$B$12 -> 51.246027 | D17: LV ACB / switchboard rating | E17: =IFERROR(INDEX(Std_Sizes!$E$3:$E$7,COUNTIF(Std_Sizes!$E$3:$E$7,"<"&(C17))+1),"EXCEEDS LIST") -> 65 | F17: =IF(E17>=C17,"OK","FAIL") -> OK
A18: F3 UPS output board (on static bypass) | B18: =B17+SQRT(Cables!$M$5^2+Cables!$N$5^2)*Cables!$E$5/Cables!$J$5 -> 5.8324271 | C18: =Inputs!$B$19/(SQRT(3)*B18/1000)/1000 -> 41.080729 | D18: UPS output board must withstand bypass fault | E18: =IFERROR(INDEX(Std_Sizes!$E$3:$E$7,COUNTIF(Std_Sizes!$E$3:$E$7,"<"&(C18))+1),"EXCEEDS LIST") -> 50 | F18: =IF(E18>=C18,"OK","FAIL") -> OK
A19: F4 PDU incomer | B19: =B18+SQRT(Cables!$M$6^2+Cables!$N$6^2)*Cables!$E$6/Cables!$J$6 -> 8.0167176 | C19: =Inputs!$B$19/(SQRT(3)*B19/1000)/1000 -> 29.887589 | D19: PDU incomer breaker | E19: =IFERROR(INDEX(Std_Sizes!$E$3:$E$7,COUNTIF(Std_Sizes!$E$3:$E$7,"<"&(C19))+1),"EXCEEDS LIST") -> 36 | F19: =IF(E19>=C19,"OK","FAIL") -> OK
A20: F5 Rack branch (phase-neutral) | B20: =B19+2*SQRT(Cables!$M$8^2+Cables!$N$8^2)*Cables!$E$8 -> 204.58032 | C20: =Inputs!$B$49/(B20/1000)/1000 -> 1.1242528 | D20: Rack MCB (line-neutral loop, 2 x branch cable) | E20: =IFERROR(INDEX(Std_Sizes!$H$3:$H$6,COUNTIF(Std_Sizes!$H$3:$H$6,"<"&(C20))+1),"EXCEEDS LIST") -> 6 | F20: =IF(E20>=C20,"OK","FAIL") -> OK
A21: F6 Generator terminals | C21: =Sizing!$B$41/Inputs!$B$40/1000 -> 28.983447 | D21: Generator contribution only; gensets are not paralleled with the utility | E21: =E17 -> 65 | F21: =IF(E21>=C21,"OK","FAIL") -> OK

Sheet Protection
A1: Step 4b: Protection devices and coordination
A2: Settings are proposed starting values for the coordination study. Blue = editable setting.
A4: Device / location | B4: Load current (A) | C4: Frame (A) | D4: Ir setting (A) | E4: Isd multiple (x Ir) | F4: Isd pickup (A) | G4: tsd delay (s) | H4: Fault at device (kA) | I4: Breaking rating (kA) | J4: Frame >= Ir >= Ib | K4: Isd < fault current (sensitivity) | L4: Rating >= fault
A5: LV main ACB (TR secondary) | B5: =Sizing!$B$8 -> 3478.0137 | C5: =IFERROR(INDEX(Std_Sizes!$G$3:$G$13,COUNTIF(Std_Sizes!$G$3:$G$13,"<"&(B5))+1),"EXCEEDS LIST") -> 4000 | D5: =MIN(C5,ROUNDUP(B5*1.05/50,0)*50) -> 3700 | E5: 5 | F5: =E5*D5 -> 18500 | G5: 0.4 | H5: =ShortCircuit!$C$17 -> 51.246027 | I5: =ShortCircuit!$E$17 -> 65 | J5: =IF(AND(C5>=D5,D5>=B5),"OK","FAIL") -> OK | K5: =IF(F5<H5*1000,"OK","CHECK") -> OK | L5: =IF(I5>=H5,"OK","FAIL") -> OK
A6: UPS input ACB | B6: =Sizing!$B$21 -> 1932.2298 | C6: =IFERROR(INDEX(Std_Sizes!$G$3:$G$13,COUNTIF(Std_Sizes!$G$3:$G$13,"<"&(B6*1.25))+1),"EXCEEDS LIST") -> 2500 | D6: =MIN(C6,ROUNDUP(B6*1.05/50,0)*50) -> 2050 | E6: 6 | F6: =E6*D6 -> 12300 | G6: 0.3 | H6: =ShortCircuit!$C$17 -> 51.246027 | I6: =ShortCircuit!$E$17 -> 65 | J6: =IF(AND(C6>=D6,D6>=B6),"OK","FAIL") -> OK | K6: =IF(F6<H6*1000,"OK","CHECK") -> OK | L6: =IF(I6>=H6,"OK","FAIL") -> OK
A7: UPS output ACB | B7: =Sizing!$B$19 -> 1669.4466 | C7: =IFERROR(INDEX(Std_Sizes!$G$3:$G$13,COUNTIF(Std_Sizes!$G$3:$G$13,"<"&(B7*1.25))+1),"EXCEEDS LIST") -> 2500 | D7: =MIN(C7,ROUNDUP(B7*1.05/50,0)*50) -> 1800 | E7: 6 | F7: =E7*D7 -> 10800 | G7: 0.2 | H7: =ShortCircuit!$C$18 -> 41.080729 | I7: =ShortCircuit!$E$18 -> 50 | J7: =IF(AND(C7>=D7,D7>=B7),"OK","FAIL") -> OK | K7: =IF(F7<H7*1000,"OK","CHECK") -> OK | L7: =IF(I7>=H7,"OK","FAIL") -> OK
A8: PDU main MCCB | B8: =Sizing!$B$48 -> 556.48219 | C8: =IFERROR(INDEX(Std_Sizes!$G$3:$G$13,COUNTIF(Std_Sizes!$G$3:$G$13,"<"&(B8*1.25))+1),"EXCEEDS LIST") -> 800 | D8: =MIN(C8,ROUNDUP(B8*1.05/50,0)*50) -> 600 | E8: 8 | F8: =E8*D8 -> 4800 | G8: 0.1 | H8: =ShortCircuit!$C$19 -> 29.887589 | I8: =ShortCircuit!$E$19 -> 36 | J8: =IF(AND(C8>=D8,D8>=B8),"OK","FAIL") -> OK | K8: =IF(F8<H8*1000,"OK","CHECK") -> OK | L8: =IF(I8>=H8,"OK","FAIL") -> OK
A9: Mechanical MCC feeder ACB | B9: =Cables!$B$7 -> 752.88766 | C9: =IFERROR(INDEX(Std_Sizes!$G$3:$G$13,COUNTIF(Std_Sizes!$G$3:$G$13,"<"&(B9*1.25))+1),"EXCEEDS LIST") -> 1000 | D9: =MIN(C9,ROUNDUP(B9*1.05/50,0)*50) -> 800 | E9: 6 | F9: =E9*D9 -> 4800 | G9: 0.3 | H9: =ShortCircuit!$C$17 -> 51.246027 | I9: =ShortCircuit!$E$17 -> 65 | J9: =IF(AND(C9>=D9,D9>=B9),"OK","FAIL") -> OK | K9: =IF(F9<H9*1000,"OK","CHECK") -> OK | L9: =IF(I9>=H9,"OK","FAIL") -> OK
A10: Rack branch MCB (C-curve) | B10: =Sizing!$B$51 -> 22.883295 | C10: =Inputs!$B$50 -> 32 | D10: =Inputs!$B$50 -> 32 | E10: 10 | F10: =E10*D10 -> 320 | G10: 0 | H10: =ShortCircuit!$C$20 -> 1.1242528 | I10: =ShortCircuit!$E$20 -> 6 | J10: =IF(AND(C10>=D10,D10>=B10),"OK","FAIL") -> OK | K10: =IF(F10<H10*1000,"OK","CHECK") -> OK | L10: =IF(I10>=H10,"OK","FAIL") -> OK
A12: MV transformer protection (11 kV relay, IEC Normal Inverse)
A13: Parameter | B13: Value | C13: Unit | D13: Remark
A14: Transformer MV full-load current | B14: =Sizing!$B$9 -> 131.21597 | C14: A
A15: Relay time multiplier (TMS) | B15: 0.25 | C15: - | D15: Chosen to grade above LV main ACB
A16: 51 pickup = 1.25 x FLC (rounded up to 10 A) | B16: =ROUNDUP(1.25*Protection!$B$14/10,0)*10 -> 170 | C16: A | D16: Primary side
A17: Max LV bus fault reflected to 11 kV | B17: =ShortCircuit!$C$17*1000*Inputs!$B$19/(Inputs!$B$18*1000) -> 1933.3728 | C17: A
A18: Fault multiple of pickup | B18: =Protection!$B$17/Protection!$B$16 -> 11.372781 | C18: x
A19: Relay operating time at that fault | B19: =Protection!$B$15*0.14/(Protection!$B$18^0.02-1) -> 0.70244418 | C19: s | D19: IEC NI: t = TMS x 0.14 / ((I/Is)^0.02 - 1)
A20: Grading margin over LV main ACB tsd | B20: =Protection!$B$19-Protection!$G$5 -> 0.30244418 | C20: s | D20: Need >= 0.3 s
A21: Grading check | B21: =IF(Protection!$B$20>=0.3,"OK","INCREASE TMS") -> OK
A22: 50 pickup = 1.15 x reflected LV fault (rounded up to 100 A) | B22: =ROUNDUP(1.15*Protection!$B$17/100,0)*100 -> 2300 | C22: A | D22: Must not trip for LV-side faults
A23: Transformer inrush (10 x FLC) | B23: =10*Protection!$B$14 -> 1312.1597 | C23: A
A24: 50 pickup above inrush and below MV bus fault | B24: =IF(AND(Protection!$B$22>Protection!$B$23,Protection!$B$22<ShortCircuit!$C$16*1000),"OK","CHECK") -> OK
A26: Selectivity chain (fault on downstream side, trip delays)
A27: Upstream device | B27: Delay (s) | C27: Downstream device | D27: Delay (s) | E27: Margin (s) | F27: Check (>= 0.1 s)
A28: UPS output ACB | B28: =Protection!$G$7 -> 0.2 | C28: PDU main MCCB | D28: =Protection!$G$8 -> 0.1 | E28: =B28-D28 -> 0.1 | F28: =IF(E28>=0.1,"OK","FAIL") -> OK
A29: UPS input ACB | B29: =Protection!$G$6 -> 0.3 | C29: UPS output ACB | D29: =Protection!$G$7 -> 0.2 | E29: =B29-D29 -> 0.1 | F29: =IF(E29>=0.1,"OK","FAIL") -> OK
A30: LV main ACB | B30: =Protection!$G$5 -> 0.4 | C30: UPS input ACB | D30: =Protection!$G$6 -> 0.3 | E30: =B30-D30 -> 0.1 | F30: =IF(E30>=0.1,"OK","FAIL") -> OK
A31: LV main ACB | B31: =Protection!$G$5 -> 0.4 | C31: Mechanical MCC feeder | D31: =Protection!$G$9 -> 0.3 | E31: =B31-D31 -> 0.1 | F31: =IF(E31>=0.1,"OK","FAIL") -> OK
A32: 11 kV relay (51) | B32: =Protection!$B$19 -> 0.70244418 | C32: LV main ACB | D32: =Protection!$G$5 -> 0.4 | E32: =B32-D32 -> 0.30244418 | F32: =IF(E32>=0.3,"OK","FAIL") -> OK
A34: Other protection and safety provisions:
A35: Transformer: Buchholz relay, winding and oil temperature (WTI/OTI), pressure relief valve; restricted earth fault (REF) on LV neutral.
A36: Generator: 27/59 voltage, 81 frequency, 50/51 overcurrent, 32 reverse power, 87G differential, 64 earth fault, emergency stop.
A37: Earthing: TN-S at LV, solidly earthed transformer neutral, earth pit resistance target < 1 Ω (IS 3043), separate IT/clean earth bonded at one point.
A38: Surge protection: Type 1 at LV main board, Type 2 at UPS input and PDU, Type 3 at critical rack strips (IEC 61643).
A39: Arc flash: not computed here. Recommended as an extension (IEEE 1584) once the final breaker data is available.

Sheet Reliability
A1: Step 5: Reliability and availability analysis
A2: Series reliability block model per path; 2N combines two independent paths with a common-cause factor. Component data are ILLUSTRATIVE ASSUMPTIONS: replace with IEEE 493 / vendor data.
A4: Parameter | B4: Value | C4: Unit | D4: Remark
A5: Utility supply availability (per feeder) | B5: 0.995 | C5: - | D5: ASSUMPTION. Replace with DISCOM reliability data (SAIDI/SAIFI) for the feeder
A6: Generator start-on-demand availability | B6: 0.99 | C6: - | D6: ASSUMPTION. Depends on maintenance and testing regime
A7: Common-cause factor between paths (beta) | B7: 0.01 | C7: - | D7: ASSUMPTION. Fraction of path failures that hit both paths (shared room, fire, human error)
A8: Power source availability (utility with generator backup) | B8: =1-(1-Reliability!$B$5)*(1-Reliability!$B$6) -> 0.99995 | C8: - | D8: Formula: 1 - (1 - A_utility) x (1 - A_generator)
A10: Component (series, per path) | B10: MTBF (h) | C10: MTTR (h) | D10: Unavailability | E10: Availability
A11: MV switchgear | B11: 500000 | C11: 24 | D11: =C11/(B11+C11) -> 4.7997696e-05 | E11: =1-D11 -> 0.999952
A12: Transformer | B12: 300000 | C12: 130 | D12: =C12/(B12+C12) -> 0.00043314564 | E12: =1-D12 -> 0.99956685
A13: LV essential switchboard | B13: 1000000 | C13: 24 | D13: =C13/(B13+C13) -> 2.3999424e-05 | E13: =1-D13 -> 0.999976
A14: ATS | B14: 250000 | C14: 8 | D14: =C14/(B14+C14) -> 3.1998976e-05 | E14: =1-D14 -> 0.999968
A15: UPS module incl. static switch | B15: 120000 | C15: 8 | D15: =C15/(B15+C15) -> 6.6662223e-05 | E15: =1-D15 -> 0.99993334
A16: Battery system | B16: 100000 | C16: 8 | D16: =C16/(B16+C16) -> 7.9993601e-05 | E16: =1-D16 -> 0.99992001
A17: UPS output board | B17: 1000000 | C17: 24 | D17: =C17/(B17+C17) -> 2.3999424e-05 | E17: =1-D17 -> 0.999976
A18: PDU | B18: 500000 | C18: 4 | D18: =C18/(B18+C18) -> 7.999936e-06 | E18: =1-D18 -> 0.999992
A19: RPP | B19: 1000000 | C19: 4 | D19: =C19/(B19+C19) -> 3.999984e-06 | E19: =1-D19 -> 0.999996
A22: Configuration | B22: Availability | C22: Unavailability | D22: Downtime (h/year) | E22: Downtime (min/year) | F22: Availability class (Uptime Institute figures)
A23: N: single path, no redundancy | B23: =Reliability!$B$8*PRODUCT(E11:E19) -> 0.9992304 | C23: =1-B23 -> 0.00076960339 | D23: =C23*8760 -> 6.7417257 | E23: =C23*525600 -> 404.50354 | F23: =IF(B23>=0.99995,"Tier IV level (>= 99.995%)",IF(B23>=0.99982,"Tier III level (>= 99.982%)",IF(B23>=0.99741,"Tier II level (>= 99.741%)","Tier I level or below"))) -> Tier II level (>= 99.741%)
A24: N+1: parallel redundant UPS, rest single path | B24: =Reliability!$B$8*PRODUCT(E11:E14)*E17*E18*E19*(1-((1-E15*E16)^2+Reliability!$B$7*(1-E15*E16))) -> 0.99937547 | C24: =1-B24 -> 0.00062453135 | D24: =C24*8760 -> 5.4708947 | E24: =C24*525600 -> 328.25368 | F24: =IF(B24>=0.99995,"Tier IV level (>= 99.995%)",IF(B24>=0.99982,"Tier III level (>= 99.982%)",IF(B24>=0.99741,"Tier II level (>= 99.741%)","Tier I level or below"))) -> Tier II level (>= 99.741%)
A25: 2N: two independent paths (this design) | B25: =1-((1-B23)^2+Reliability!$B$7*(1-B23)) -> 0.99999171 | C25: =1-B25 -> 8.2883233e-06 | D25: =C25*8760 -> 0.072605712 | E25: =C25*525600 -> 4.3563427 | F25: =IF(B25>=0.99995,"Tier IV level (>= 99.995%)",IF(B25>=0.99982,"Tier III level (>= 99.982%)",IF(B25>=0.99741,"Tier II level (>= 99.741%)","Tier I level or below"))) -> Tier IV level (>= 99.995%)
A27: Notes:
A28: 1. Availability class is a calculated comparison only. Formal Tier certification depends on topology and operations, not on this figure.
A29: 2. The transformer dominates single-path unavailability because of its long repair time; this is why 2N (or a spare transformer) matters.
A30: 3. 2N unavailability = U_path² + β·U_path. Without the β term, 2N would appear unrealistically perfect.
A31: 4. Rack-level dual-corded PSU failure and operator error are not modelled.

Sheet Failure_Scenarios
A1: Step 5b: Failure scenario table (FMEA style)
A2: What happens when a component fails. The last column is calculated live from the sizing sheets.
A4: ID | B4: Failure event | C4: System response | D4: Effect on IT load | E4: Remaining risk / mitigation | F4: Live check
A5: F1 | B5: Utility outage on both feeders | C5: ATS senses loss, both gensets start and transfer in about 10-15 s; UPS batteries carry the load meanwhile. | D5: None | E5: Generators become the single source of energy. Fuel autonomy and monthly on-load tests are critical. | F5: ="Gen load each = "&TEXT(Sizing!$B$39,"0%")&" of kW rating; battery = "&Inputs!$B$30&" min; fuel = "&Inputs!$B$42&" h" -> Gen load each = 38% of kW rating; battery = 10 min; fuel = 24 h
A6: F2 | B6: Utility feeder A lost (B healthy) | C6: Path A ATS starts Gen A; UPS A rides through on battery. | D6: None | E6: Path B untouched. If Gen A fails to start, see F5. | F6: ="UPS-A battery autonomy = "&Inputs!$B$30&" min" -> UPS-A battery autonomy = 10 min
A7: F3 | B7: Transformer A internal fault | C7: MV relay / Buchholz trips VCB. Path A LV board loses utility; ATS may start Gen A. | D7: None (dual-corded loads stay on B) | E7: Longest repair time in the system. Path B now runs at 100% of facility load; no redundancy until repair. | F7: ="TR-B loading at failover = "&TEXT(Sizing!$B$11,"0%")&" of "&Sizing!$B$7&" kVA" -> TR-B loading at failover = 67% of 2500 kVA
A8: F4 | B8: UPS A module failure | C8: UPS transfers to static bypass if available, otherwise path A output is lost. Dual-corded racks continue from B. | D8: None | E8: UPS B now carries all IT load. | F8: ="UPS-B loading at failover = "&TEXT(Sizing!$B$18,"0%")&" (limit 100%)" -> UPS-B loading at failover = 83% (limit 100%)
A9: F5 | B9: Generator A fails to start during utility outage | C9: UPS A runs on battery until autonomy ends, then path A de-energises. | D9: None while path B is healthy | E9: If Gen B also fails, IT stops after battery autonomy. Mitigation: N+1 gensets, monthly testing, fuel quality management. | F9: ="Battery ride-through = "&Inputs!$B$30&" min" -> Battery ride-through = 10 min
A10: F6 | B10: PDU A failure | C10: Downstream racks lose A feed; B feed takes the full rack load. | D10: None | E10: Rack feeds on B carry 100% of rack load. | F10: ="Rack feed current on B = "&TEXT(Sizing!$B$51,"0.0")&" A vs "&Inputs!$B$50&" A breaker (80% rule)" -> Rack feed current on B = 22.9 A vs 32 A breaker (80% rule)
A11: F7 | B11: Planned maintenance of entire path A (concurrent maintainability) | C11: Path A isolated at LV main and UPS output; B carries everything. | D11: None | E11: Facility is single-path during the work. Schedule in low-risk windows. | F11: ="Path B loading: TR "&TEXT(Sizing!$B$11,"0%")&", UPS "&TEXT(Sizing!$B$18,"0%")&", PDU "&TEXT(Sizing!$B$47,"0%") -> Path B loading: TR 67%, UPS 83%, PDU 66%
A12: F8 | B12: Short circuit at a PDU | C12: PDU main MCCB clears in its instantaneous / short-time zone; upstream devices stay closed by time grading. | D12: None | E12: Needs the coordination study to confirm selectivity. | F12: ="Fault at PDU = "&TEXT(ShortCircuit!$C$19,"0.0")&" kA; PDU main tsd = "&Protection!$G$8&" s, UPS output tsd = "&Protection!$G$7&" s" -> Fault at PDU = 29.9 kA; PDU main tsd = 0.1 s, UPS output tsd = 0.2 s
A13: F9 | B13: Common-cause event (fire / flood in a shared electrical room) | C13: Both paths lost if A and B equipment share a room or cable route. | D13: Total outage | E13: Physical separation: separate fire-rated rooms and cable routes for A and B. This is the main 2N weakness. | F13: ="Common-cause factor assumed = "&TEXT(Reliability!$B$7,"0.0%") -> Common-cause factor assumed = 1.0%
A14: F10 | B14: Single-corded load while STS fails | C14: Single-corded equipment fed through STS loses supply if the STS itself fails or if both sources fail. | D14: Only single-corded loads | E14: Minimise single-corded equipment; use dual-corded or rack-level ATS. | F14: ="Static transfer time is typically 4-8 ms (vendor data)" -> Static transfer time is typically 4-8 ms (vendor data)

Sheet BOM
A1: Step 7: Equipment list / bill of quantities (no prices)
A2: Quantity = per-path quantity x multiplier. Multiplier 2 for A/B items, 1 for shared items.
A4: # | B4: Item | C4: Rating / description | D4: Qty per path | E4: Multiplier | F4: Total qty | G4: Remarks
A5: 1 | B5: MV switchgear panel | C5: ="11 kV VCB panel, "&630&" A, "&ShortCircuit!$E$16&" kA / 3 s" -> 11 kV VCB panel, 630 A, 16 kA / 3 s | D5: 2 | E5: 2 | F5: =D5*E5 -> 4 | G5: Incomer + transformer feeder per path
A6: 2 | B6: Distribution transformer | C6: =Sizing!$B$7&" kVA, 11/0.415 kV, Dyn11, Z = 6.25%, ONAN" -> 2500 kVA, 11/0.415 kV, Dyn11, Z = 6.25%, ONAN | D6: 1 | E6: 2 | F6: =D6*E6 -> 2 | G6: Cast resin or oil, per local practice
A7: 3 | B7: Busduct, transformer to LV board | C7: =Sizing!$B$13&" A busduct" -> 4000 A busduct | D7: 1 | E7: 2 | F7: =D7*E7 -> 2
A8: 4 | B8: LV main ACB | C8: =Protection!$C$5&" A frame, Ir = "&Protection!$D$5&" A, "&ShortCircuit!$E$17&" kA" -> 4000 A frame, Ir = 3700 A, 65 kA | D8: 1 | E8: 2 | F8: =D8*E8 -> 2
A9: 5 | B9: Automatic transfer switch (ATS) | C9: =Sizing!$B$13&" A, 4-pole, utility / generator" -> 4000 A, 4-pole, utility / generator | D9: 1 | E9: 2 | F9: =D9*E9 -> 2
A10: 6 | B10: Diesel generator set | C10: =Sizing!$B$36&" kVA standby, 415 V, "&Sizing!$B$37&" kW" -> 2500 kVA standby, 415 V, 2000 kW | D10: =Sizing!$B$40 -> 1 | E10: 2 | F10: =D10*E10 -> 2 | G10: Set Inputs extra gensets = 1 for N+1 per path
A11: 7 | B11: Fuel storage tank | C11: =TEXT(Sizing!$B$43,"#,##0")&" L (for "&Inputs!$B$42&" h at failover load)" -> 9,720 L (for 24 h at failover load) | D11: =Sizing!$B$40 -> 1 | E11: 2 | F11: =D11*E11 -> 2 | G11: Local fire and explosives rules apply
A12: 8 | B12: LV essential switchboard | C12: ="Form 4b, incl. UPS and mechanical feeders" -> Form 4b, incl. UPS and mechanical feeders | D12: 1 | E12: 2 | F12: =D12*E12 -> 2
A13: 9 | B13: UPS | C13: =Sizing!$B$16&" kVA / kW, double conversion, IEC 62040" -> 1200 kVA / kW, double conversion, IEC 62040 | D13: 1 | E13: 2 | F13: =D13*E13 -> 2
A14: 10 | B14: Battery string | C14: =Inputs!$B$36&" Ah, "&Inputs!$B$31&" cells (480 V), VRLA" -> 300 Ah, 240 cells (480 V), VRLA | D14: =Sizing!$B$28 -> 4 | E14: 2 | F14: =D14*E14 -> 8 | G14: Strings per UPS; validate with vendor tables
A15: 11 | B15: UPS output board | C15: ="With maintenance bypass" -> With maintenance bypass | D15: 1 | E15: 2 | F15: =D15*E15 -> 2
A16: 12 | B16: PDU | C16: =Sizing!$B$46&" kVA, 415/230 V, with isolation transformer or static" -> 400 kVA, 415/230 V, with isolation transformer or static | D16: =Inputs!$B$45 -> 4 | E16: 2 | F16: =D16*E16 -> 8
A17: 13 | B17: RPP (remote power panel) | C17: ="42-way, 32 A outgoing MCBs, metered" -> 42-way, 32 A outgoing MCBs, metered | D17: =Sizing!$B$50 -> 8 | E17: 2 | F17: =D17*E17 -> 16
A18: 14 | B18: Cable sets, LV board to UPS input | C18: =Cables!$J$5&" x 3 x 1C "&Cables!$G$5&" mm² Cu XLPE + PE" -> 5 x 3 x 1C 300 mm² Cu XLPE + PE | D18: =Cables!$J$5 -> 5 | E18: 2 | F18: =D18*E18 -> 10 | G18: Qty = parallel runs
A19: 15 | B19: Cable sets, UPS output board to PDU | C19: =Cables!$J$6&" x 3 x 1C "&Cables!$G$6&" mm² Cu XLPE + PE" -> 2 x 3 x 1C 185 mm² Cu XLPE + PE | D19: =Cables!$J$6*Inputs!$B$45 -> 8 | E19: 2 | F19: =D19*E19 -> 16 | G19: Qty = runs x PDUs
A20: 16 | B20: Cable sets, LV board to mechanical MCC | C20: =Cables!$J$7&" x 3 x 1C "&Cables!$G$7&" mm² Cu XLPE + PE" -> 2 x 3 x 1C 240 mm² Cu XLPE + PE | D20: =Cables!$J$7 -> 2 | E20: 2 | F20: =D20*E20 -> 4
A21: 17 | B21: Rack branch cables | C21: ="1-phase, "&Cables!$G$8&" mm² Cu XLPE, one per rack feed" -> 1-phase, 6 mm² Cu XLPE, one per rack feed | D21: =Inputs!$B$6 -> 200 | E21: 2 | F21: =D21*E21 -> 400 | G21: A feed and B feed for every rack
A22: 18 | B22: Rack PDU strips | C22: ="Metered, 32 A, one per feed" -> Metered, 32 A, one per feed | D22: =Inputs!$B$6 -> 200 | E22: 2 | F22: =D22*E22 -> 400
A23: 19 | B23: IT racks | C23: ="Dual-corded racks" -> Dual-corded racks | D23: =Inputs!$B$6 -> 200 | E23: 1 | F23: =D23*E23 -> 200 | G23: Shared between paths
A24: 20 | B24: Static transfer switch (STS) | C24: ="100 A class, for single-corded loads" -> 100 A class, for single-corded loads | D24: 2 | E24: 1 | F24: =D24*E24 -> 2 | G24: PLACEHOLDER quantity. Depends on single-corded device count
A25: 21 | B25: Surge protective devices | C25: ="Type 1 at LV main, Type 2 at UPS input and PDU" -> Type 1 at LV main, Type 2 at UPS input and PDU | D25: 3 | E25: 2 | F25: =D25*E25 -> 6 | G25: Sets

Sheet Std_Sizes
A1: Standard ratings and cable data
A2: Transformer (kVA) | B2: UPS (kVA) | C2: Genset (kVA) | D2: PDU (kVA) | E2: LV breaking (kA) | F2: MV breaking (kA) | G2: Breaker / busduct frame (A) | H2: Branch MCB breaking (kA) | K2: Cu XLPE size (mm²) | L2: Ampacity in air @30°C (A) | M2: R at 90°C (Ω/km) | N2: X (Ω/km)
A3: 1000 | B3: 500 | C3: 1250 | D3: 100 | E3: 36 | F3: 12.5 | G3: 630 | H3: 6 | K3: 6 | L3: 54 | M3: 3.93 | N3: 0.1
A4: 1250 | B4: 600 | C4: 1500 | D4: 150 | E4: 50 | F4: 16 | G4: 800 | H4: 10 | K4: 10 | L4: 75 | M4: 2.33 | N4: 0.094
A5: 1600 | B5: 800 | C5: 1750 | D5: 200 | E5: 65 | F5: 20 | G5: 1000 | H5: 15 | K5: 16 | L5: 100 | M5: 1.47 | N5: 0.09
A6: 2000 | B6: 1000 | C6: 2000 | D6: 250 | E6: 80 | F6: 25 | G6: 1250 | H6: 25 | K6: 25 | L6: 133 | M6: 0.927 | N6: 0.086
A7: 2500 | B7: 1200 | C7: 2250 | D7: 300 | E7: 100 | F7: 31.5 | G7: 1600 | K7: 35 | L7: 164 | M7: 0.668 | N7: 0.083
A8: 3150 | B8: 1250 | C8: 2500 | D8: 400 | F8: 40 | G8: 2000 | K8: 50 | L8: 198 | M8: 0.494 | N8: 0.081
A9: 4000 | B9: 1500 | C9: 2750 | D9: 500 | G9: 2500 | K9: 70 | L9: 253 | M9: 0.342 | N9: 0.078
B10: 1600 | C10: 3000 | G10: 3200 | K10: 95 | L10: 306 | M10: 0.246 | N10: 0.076
B11: 2000 | G11: 4000 | K11: 120 | L11: 354 | M11: 0.195 | N11: 0.075
G12: 5000 | K12: 150 | L12: 402 | M12: 0.159 | N12: 0.074
G13: 6300 | K13: 185 | L13: 460 | M13: 0.126 | N13: 0.073
K14: 240 | L14: 546 | M14: 0.096 | N14: 0.072
K15: 300 | L15: 631 | M15: 0.077 | N15: 0.071
K17: Note: cable values are indicative (1.1 kV Cu XLPE, single-core trefoil in air). Verify with the manufacturer's datasheet and installation method before procurement.
